<?xml version="1.0"?>
<robot 
  name="differential_drive">
  <!-- Base Link -->
  <link name="base_link">
<!-- Base Link -->
    <visual>
        <origin xyz="0 0 0" rpy="0 0 0"/>
        <geometry>
            <box size="0.5 0.5 0.25"/>
        </geometry>
        <material name="blue">
            <color rgba="0 0.5 1 1"/>
        </material>
    </visual>
    <!-- Caster -->
    <visual name="caster">
        <origin xyz="0.2 0.0 -0.125" rpy="0.0 0.0 0.0"/>
        <geometry>
            <sphere radius="0.05"/>
        </geometry>
    </visual>
  </link>
<!-- Right Wheel -->
  <link name="right_wheel">
    <visual>
        <geometry>
            <cylinder length="0.1" radius="0.2"/>
        </geometry>
        <origin xyz="0 0 0" rpy="-1.570796 0 0"/>
        <material name="black">
            <color rgba="0.05 0.05 0.05 1.0"/>
        </material>
    </visual>
  </link>
<!-- Left Wheel -->
  <link name="left_wheel">
    <visual>
        <geometry>
            <cylinder length="0.1" radius="0.2"/>
        </geometry>
        <origin xyz="0 0 0" rpy="1.570796 0 0"/>
        <material name="black">
            <color rgba="0.05 0.05 0.05 1.0"/>
        </material>
    </visual>
  </link>
<!-- Right Wheel Joint -->
  <joint name="right_wheel_joint" type="continuous">
    <origin xyz="0 -0.3 0" rpy="0 0 0"/>
    <parent link="base_link"/>
    <child link="right_wheel"/>
    <axis xyz="0 1 0"/>
  </joint>
<!-- Left Wheel Joint -->
  <joint name="left_wheel_joint" type="continuous">
    <origin xyz="0 0.3 0" rpy="0 0 0"/>
    <parent link="base_link"/>
    <child link="left_wheel"/>
    <axis xyz="0 1 0"/>
  </joint>
</robot>